Workbook

Sheet Overview
A1: Post-Flight Data Sheet AE3202
A3: date of flight: | D3: 43900 | F3: T/O time:
A4: flight number: | D4: 2 | F4: LND time:
A6: Weights
D7: name | H7: mass [kg]
A8: pilot 1: | D8: Hans Mulder | H8: 90
A9: pilot 2: | D9: Alexander in 't Veld | H9: 98
A10: co-ordinator: | D10: Maurice+Bram | H10: 175
A11: observer 1L: | D11: Jesse de Vries | H11: 82
A12: observer 1R: | D12: Dennis Spelt | H12: 71
A13: observer 2L: | D13: Mattis Hilgeman | H13: 82
A14: observer 2R: | D14: Patrick Blok | H14: 67
A15: observer 3L: | D15: Tim Jacobs | H15: 81
A16: observer 3R: | D16: Jens Dijk | H16: 84
A18: block fuel [lbs]: | D18: 2714
A21: Stationary measurements CL-CD Series 1
A23: Aircraft configuration: | E23: clean
A25: , | B25: time | C25: ET* | D25: hp | E25: IAS | F25: a | G25: FFl | H25: FFr | I25: F. used | J25: TAT
B26: [hrs:min] | C26: [sec] | D26: [ft] | E26: [kts] | F26: [deg] | G26: [lbs/hr] | H26: [lbs/hr] | I26: [lbs] | J26: [°C]
A28: 1 | B28: =averaging!I10 -> 0.015405093 | C28: - | D28: =averaging!B10 -> 16530 | E28: =averaging!C10 -> 241 | F28: =averaging!H10 -> 1.5 | G28: =averaging!E10 -> 679 | H28: =averaging!F10 -> 707 | I28: =averaging!G10 -> 505.33333 | J28: =averaging!D10 -> -8.05
A29: 2 | B29: =averaging!I18 -> 0.017390046 | C29: - | D29: =averaging!B18 -> 16530 | E29: =averaging!C18 -> 221.16667 | F29: =averaging!H18 -> 2 | G29: =averaging!E18 -> 572.5 | H29: =averaging!F18 -> 599.16667 | I29: =averaging!G18 -> 565.33333 | J29: =averaging!D18 -> -9.6833333
A30: 3 | B30: =averaging!I26 -> 0.018805941 | C30: - | D30: =averaging!B26 -> 16483.333 | E30: =averaging!C26 -> 186 | F30: =averaging!H26 -> 3.4 | G30: =averaging!E26 -> 475.16667 | H30: =averaging!F26 -> 497.5 | I30: =averaging!G26 -> 594.16667 | J30: =averaging!D26 -> -12.15
A31: 4 | B31: =averaging!I34 -> 0.020657793 | C31: - | D31: =averaging!B34 -> 16060 | E31: =averaging!C34 -> 161 | F31: =averaging!H34 -> 4.9 | G31: =averaging!E34 -> 414.16667 | H31: =averaging!F34 -> 441.16667 | I31: =averaging!G34 -> 626.66667 | J31: =averaging!D34 -> -13.3
A32: 5 | B32: =averaging!I42 -> 0.021983025 | C32: - | D32: =averaging!B42 -> 16001.667 | E32: =averaging!C42 -> 131.5 | F32: =averaging!H42 -> 7.9 | G32: =averaging!E42 -> 364.83333 | H32: =averaging!F42 -> 384.33333 | I32: =averaging!G42 -> 647.5 | J32: =averaging!D42 -> -15.5
A33: 6 | B33: =averaging!I50 -> 0.023094136 | C33: - | D33: =averaging!B50 -> 16010 | E33: =averaging!C50 -> 111 | F33: =averaging!H50 -> 11.35 | G33: =averaging!E50 -> 379 | H33: =averaging!F50 -> 404.33333 | I33: =averaging!G50 -> 666.5 | J33: =averaging!D50 -> -16.5
A34: 7 | B34: =averaging!I58 -> 0 | C34: -
C35: * ET = Elapsed Time
A37: Stationary measurements CL - CD Series 2
A39: Aircraft configuration :
A41: nr. | B41: time | C41: ET* | D41: hp | E41: IAS | F41: a | G41: FFl | H41: FFr | I41: F. used | J41: TAT
B42: [hh:mm] | C42: [sec] | D42: [ft] | E42: [kts] | F42: [deg] | G42: [lbs/hr] | H42: [lbs/hr] | I42: [lbs] | J42: [°C]
A44: 1 | C44: -
A45: 2 | C45: -
A46: 3 | C46: -
A47: 4 | C47: -
A48: 5 | C48: -
A49: 6 | C49: -
A50: 7 | C50: -
C51: * ET = Elapsed Time
A52: Stationary measurements Elevator Trim Curve
...

Sheet averaging
B1: Series 1 measurements | L1: Series 2 measurements
B2: h | C2: V | D2: TAT | E2: FFI | F2: FFR | G2: Wf | H2: Aoa | I2: time | L2: Aoa | M2: V | N2: h | O2: TAT | P2: Fe | Q2: Wf | R2: det | S2: FFI | T2: FFR | U2: d_e | V2: time
A3: Test 1 | K3: Test 1
A4: Jesse | B4: 16530 | C4: 241 | D4: -8 | E4: 682 | F4: 707 | G4: 504 | H4: 1.5 | I4: 0.015393519 | K4: Jesse | L4: 4.6 | M4: 163 | N4: 15960 | O4: - | P4: - | Q4: - | R4: - | S4: 406 | T4: 429 | U4: -0.8 | V4: 0.025208333
A5: Dennis | B5: 16530 | C5: 241 | D5: -8 | E5: 682 | F5: 708 | G5: 508 | H5: 1.5 | I5: 0.015381944 | K5: Dennis | L5: 4.7 | M5: 163 | N5: 15960 | O5: - | P5: - | Q5: - | R5: - | S5: 406 | T5: 430 | U5: -0.8 | V5: 0.025208333
A6: Mattis | B6: 16530 | C6: 241 | D6: -8 | E6: 680 | F6: 708 | G6: 508 | H6: 1.5 | I6: 0.015405093 | K6: Mattis | L6: 4.6 | M6: 163 | N6: 15960 | O6: - | P6: -1 | Q6: - | R6: 1.6 | S6: - | T6: - | U6: - | V6: 0.025231481
A7: Patrick | B7: 16530 | C7: 241 | D7: -8 | E7: 679 | F7: 706 | G7: 505 | H7: 1.5 | I7: 0.015393519 | K7: Patrick | L7: 4.7 | M7: 163 | N7: 15960 | O7: -13.8 | P7: - | Q7: 714 | R7: - | S7: - | T7: - | U7: - | V7: 0.025196759
A8: Tim | B8: 16530 | C8: 241 | D8: -8.3 | E8: 675 | F8: 706 | G8: 503 | H8: 1.5 | I8: 0.015439815 | K8: Tim | L8: 4.6 | M8: 163 | N8: 15960 | O8: -13.8 | P8: -1 | Q8: - | R8: - | S8: - | T8: - | U8: - | V8: 0.025208333
A9: Jens | B9: 16530 | C9: 241 | D9: -8 | E9: 676 | F9: 707 | G9: 504 | H9: 1.5 | I9: 0.015416667 | K9: Jens | L9: 4.7 | M9: 162 | N9: 15960 | O9: - | P9: - | Q9: 717 | R9: 1.6 | S9: - | T9: - | U9: - | V9: 0.025219907
A10: Average | B10: =AVERAGE(B3:B9) -> 16530 | C10: =AVERAGE(C3:C9) -> 241 | D10: =AVERAGE(D3:D9) -> -8.05 | E10: =AVERAGE(E3:E9) -> 679 | F10: =AVERAGE(F3:F9) -> 707 | G10: =AVERAGE(G3:G9) -> 505.33333 | H10: =AVERAGE(H3:H9) -> 1.5 | I10: =AVERAGE(I3:I9) -> 0.015405093 | K10: Average | L10: =AVERAGE(L4:L9) -> 4.65 | M10: =AVERAGE(M4:M9) -> 162.83333 | N10: =AVERAGE(N4:N9) -> 15960 | O10: =AVERAGE(O4:O9) -> -13.8 | P10: =AVERAGE(P4:P9) -> -1 | Q10: =AVERAGE(Q4:Q9) -> 715.5 | R10: =AVERAGE(R4:R9) -> 1.6 | S10: =AVERAGE(S4:S9) -> 406 | ... V10: =AVERAGE(V4:V9) -> 0.025212191
A11: Test 2 | K11: Test 2
A12: Jesse | B12: 16530 | C12: 221 | D12: -9.8 | E12: 572 | F12: 599 | G12: 567 | H12: 2 | I12: 0.017418981 | K12: Jesse | L12: 5.6 | M12: 150 | N12: 16300 | O12: - | P12: - | Q12: - | R12: - | S12: 400 | T12: 423 | U12: -1.4 | V12: 0.025972222
A13: Dennis | B13: 16530 | C13: 221 | D13: -9.5 | E13: 573 | F13: 600 | G13: 565 | H13: 2 | I13: 0.017384259 | K13: Dennis | L13: 5.6 | M13: 150 | N13: 16300 | O13: - | P13: - | Q13: - | R13: - | S13: 400 | T13: 422 | U13: -1.4 | V13: 0.025983796
A14: Mattis | B14: 16530 | C14: 222 | D14: -9.5 | E14: 572 | F14: 600 | G14: 565 | H14: 2 | I14: 0.017384259 | K14: Mattis | L14: 5.6 | M14: 150 | N14: 16300 | O14: - | P14: -26 | Q14: - | R14: 1.5 | S14: - | T14: - | U14: - | V14: 0.025960648
A15: Patrick | B15: 16530 | C15: 221 | D15: -9.8 | E15: 573 | F15: 598 | G15: 565 | H15: 2 | I15: 0.017361111 | K15: Patrick | L15: 5.6 | M15: 150 | N15: 16300 | O15: -15 | P15: - | Q15: 729 | R15: - | S15: - | T15: - | U15: - | V15: 0.025949074
A16: Tim | B16: 16530 | C16: 221 | D16: -9.5 | E16: 574 | F16: 600 | G16: 564 | H16: 2 | I16: 0.017395833 | K16: Tim | L16: 5.6 | M16: 150 | N16: 16300 | O16: -15 | P16: -26 | Q16: - | R16: - | S16: - | T16: - | U16: - | V16: 0.025983796
A17: Jens | B17: 16530 | C17: 221 | D17: -10 | E17: 571 | F17: 598 | G17: 566 | H17: 2 | I17: 0.017395833 | K17: Jens | L17: 5.6 | M17: 151 | N17: 16300 | O17: - | P17: - | Q17: 732 | R17: 1.5 | S17: - | T17: - | U17: - | V17: 0.025960648
A18: Average | B18: =AVERAGE(B11:B17) -> 16530 | C18: =AVERAGE(C11:C17) -> 221.16667 | D18: =AVERAGE(D11:D17) -> -9.6833333 | E18: =AVERAGE(E11:E17) -> 572.5 | F18: =AVERAGE(F11:F17) -> 599.16667 | G18: =AVERAGE(G11:G17) -> 565.33333 | H18: =AVERAGE(H11:H17) -> 2 | I18: =AVERAGE(I11:I17) -> 0.017390046 | K18: Average | L18: =AVERAGE(L12:L17) -> 5.6 | M18: =AVERAGE(M12:M17) -> 150.16667 | N18: =AVERAGE(N12:N17) -> 16300 | O18: =AVERAGE(O12:O17) -> -15 | P18: =AVERAGE(P12:P17) -> -26 | Q18: =AVERAGE(Q12:Q17) -> 730.5 | R18: =AVERAGE(R12:R17) -> 1.5 | S18: =AVERAGE(S12:S17) -> 400 | ... V18: =AVERAGE(V12:V17) -> 0.025968364
A19: Test 3 | K19: Test 3
A20: Jesse | B20: 16480 | C20: 186 | D20: -12.3 | E20: 476 | F20: 497 | G20: 594 | H20: 3.4 | I20: 0.018831019 | K20: Jesse | L20: 6.7 | M20: 139 | N20: 16570 | O20: - | P20: - | Q20: - | R20: - | S20: 395 | T20: 417 | U20: -1.9 | V20: 0.026701389
A21: Dennis | B21: 16480 | C21: 186 | D21: -12 | E21: 475 | F21: 497 | G21: 595 | H21: 3.4 | I21: 0.018819444 | K21: Dennis | L21: 6.7 | M21: 139 | N21: 16570 | O21: - | P21: - | Q21: - | R21: - | S21: 395 | T21: 418 | U21: -1.9 | V21: 0.026689815
A22: Mattis | B22: 16490 | C22: 186 | D22: -12.3 | E22: 475 | F22: 498 | G22: 595 | H22: 3.4 | I22: 0.01880787 | K22: Mattis | L22: 6.7 | M22: 139 | N22: 16560 | O22: - | P22: -36 | Q22: - | R22: 1.5 | S22: - | T22: - | U22: - | V22: 0.026689815
A23: Patrick | B23: 16490 | C23: 186 | D23: -12 | E23: 475 | F23: 498 | G23: 593 | H23: 3.4 | I23: 0.018784722 | K23: Patrick | L23: 6.7 | M23: 139 | N23: 16570 | O23: -16 | P23: - | Q23: 742 | R23: - | S23: - | T23: - | U23: - | V23: 0.026701389
A24: Tim | B24: 16480 | C24: 186 | D24: -12 | E24: 475 | F24: 497 | G24: 592 | H24: 3.4 | I24: 0.018842593 | K24: Tim | L24: 6.7 | M24: 140 | N24: 16580 | O24: -16 | P24: -35 | Q24: - | R24: - | S24: - | T24: - | U24: - | V24: 0.026701389
A25: Jens | B25: 16480 | C25: 186 | D25: -12.3 | E25: 475 | F25: 498 | G25: 596 | H25: 3.4 | I25: 0.01875 | K25: Jens | L25: 6.7 | M25: 140 | N25: 16580 | O25: - | P25: - | Q25: 745 | R25: 1.5 | S25: - | T25: - | U25: - | V25: 0.026689815
A26: Average | B26: =AVERAGE(B19:B25) -> 16483.333 | C26: =AVERAGE(C19:C25) -> 186 | D26: =AVERAGE(D19:D25) -> -12.15 | E26: =AVERAGE(E19:E25) -> 475.16667 | F26: =AVERAGE(F19:F25) -> 497.5 | G26: =AVERAGE(G19:G25) -> 594.16667 | H26: =AVERAGE(H19:H25) -> 3.4 | I26: =AVERAGE(I19:I25) -> 0.018805941 | K26: Average | L26: =AVERAGE(L20:L25) -> 6.7 | M26: =AVERAGE(M20:M25) -> 139.33333 | N26: =AVERAGE(N20:N25) -> 16571.667 | O26: =AVERAGE(O20:O25) -> -16 | P26: =AVERAGE(P20:P25) -> -35.5 | Q26: =AVERAGE(Q20:Q25) -> 743.5 | R26: =AVERAGE(R20:R25) -> 1.5 | S26: =AVERAGE(S20:S25) -> 395 | ... V26: =AVERAGE(V20:V25) -> 0.026695602
A27: Test 4 | K27: Test 4
A28: Jesse | B28: 16060 | C28: 161 | D28: -13.3 | E28: 414 | F28: 441 | G28: 627 | H28: 5 | I28: 0.020659722 | K28: Jesse | L28: 7.6 | M28: 133 | N28: 16850 | O28: - | P28: - | Q28: - | R28: - | S28: 391 | T28: 413 | U28: -2.4 | V28: 0.027476852
A29: Dennis | B29: 16060 | C29: 161 | D29: -13.3 | E29: 414 | F29: 442 | G29: 627 | H29: 4.9 | I29: 0.020659722 | K29: Dennis | L29: 7.6 | M29: 133 | N29: 16850 | O29: - | P29: - | Q29: - | R29: - | S29: 390 | T29: 413 | U29: -2.4 | V29: 0.027476852
A30: Mattis | B30: 16060 | C30: 161 | D30: -13.3 | E30: 414 | F30: 441 | G30: 627 | H30: 4.8 | I30: 0.020648148 | K30: Mattis | L30: 7.5 | M30: 133 | N30: 16850 | O30: - | P30: -48 | Q30: - | R30: 1.5 | S30: - | T30: - | U30: - | V30: 0.027476852
A31: Patrick | B31: 16060 | C31: 161 | D31: -13.3 | E31: 415 | F31: 442 | G31: 627 | H31: 4.9 | I31: 0.020648148 | K31: Patrick | L31: 7.5 | M31: 133 | N31: 16850 | O31: -16.8 | P31: - | Q31: 757 | R31: - | S31: - | T31: - | U31: - | V31: 0.027465278
A32: Tim | B32: 16060 | C32: 161 | D32: -13.3 | E32: 414 | F32: 441 | G32: 626 | H32: 4.9 | I32: 0.020648148 | K32: Tim | L32: 7.6 | M32: 133 | N32: 16860 | O32: -17 | P32: -48 | Q32: - | R32: - | S32: - | T32: - | U32: - | V32: 0.0275
A33: Jens | B33: 16060 | C33: 161 | D33: -13.3 | E33: 414 | F33: 440 | G33: 626 | H33: 4.9 | I33: 0.02068287 | K33: Jens | L33: 7.6 | M33: 133 | N33: 16870 | O33: - | P33: - | Q33: 760 | R33: 1.5 | S33: - | T33: - | U33: - | V33: 0.027488426
A34: Average | B34: =AVERAGE(B27:B33) -> 16060 | C34: =AVERAGE(C27:C33) -> 161 | D34: =AVERAGE(D27:D33) -> -13.3 | E34: =AVERAGE(E27:E33) -> 414.16667 | F34: =AVERAGE(F27:F33) -> 441.16667 | G34: =AVERAGE(G27:G33) -> 626.66667 | H34: =AVERAGE(H27:H33) -> 4.9 | I34: =AVERAGE(I27:I33) -> 0.020657793 | K34: Average | L34: =AVERAGE(L28:L33) -> 7.5666667 | M34: =AVERAGE(M28:M33) -> 133 | N34: =AVERAGE(N28:N33) -> 16855 | O34: =AVERAGE(O28:O33) -> -16.9 | P34: =AVERAGE(P28:P33) -> -48 | Q34: =AVERAGE(Q28:Q33) -> 758.5 | R34: =AVERAGE(R28:R33) -> 1.5 | S34: =AVERAGE(S28:S33) -> 390.5 | ... V34: =AVERAGE(V28:V33) -> 0.02748071
A35: Test 5 | K35: Test 5
A36: Jesse | B36: 16010 | C36: 132 | D36: -15.5 | E36: 364 | F36: 385 | G36: 648 | H36: 7.9 | I36: 0.021990741 | K36: Jesse | L36: 4 | M36: 173 | N36: 16030 | O36: - | P36: - | Q36: - | R36: - | S36: 407 | T36: 429 | U36: -0.4 | V36: 0.028599537
A37: Dennis | B37: 16000 | C37: 131 | D37: -15.5 | E37: 365 | F37: 383 | G37: 647 | H37: 7.9 | I37: 0.021990741 | K37: Dennis | L37: 4 | M37: 173 | N37: 16030 | O37: - | P37: - | Q37: - | R37: - | S37: 407 | T37: 429 | U37: -0.4 | V37: 0.028587963
A38: Mattis | B38: 16000 | C38: 131 | D38: -15.5 | E38: 365 | F38: 385 | G38: 648 | H38: 7.9 | I38: 0.021990741 | K38: Mattis | L38: 4 | M38: 173 | N38: 16020 | O38: - | P38: 20 | Q38: - | R38: 1.5 | S38: - | T38: - | U38: - | V38: 0.028587963
A39: Patrick | B39: 16000 | C39: 132 | D39: -15.5 | E39: 364 | F39: 384 | G39: 647 | H39: 7.9 | I39: 0.021990741 | K39: Patrick | L39: 4 | M39: 173 | N39: 16020 | O39: -13.3 | P39: - | Q39: 782 | R39: - | S39: - | T39: - | U39: - | V39: 0.028599537
A40: Tim | B40: 16000 | C40: 132 | D40: -15.5 | E40: 366 | F40: 384 | G40: 647 | H40: 7.9 | I40: 0.021979167 | K40: Tim | L40: 4 | M40: 173 | N40: 16030 | O40: -13.3 | P40: 20 | Q40: - | R40: - | S40: - | T40: - | U40: - | V40: 0.028599537
...
